```
1、try
try:
    print('try...')
    r = 10 / int('a')
    print('result:',r)
except ValueError as e:
    print('ValueError:',e)
except ZeroDivisionError as e:
    print('ZeroDivisionError:',e)
#可以在except语块后面加一个else，当没有错误发生时，会自动执行else语句
else:
    print('NO Error')
finally:
    print('finally...')
print('END')
＃＃＃＃＃＃＃＃
try:
    foo()
except ValueError as e:
    print('ValueError')
except UnicodeError as e:
    print('UnicodeError')
第二个except永远也捕获不到UnicodeError，因为UnicodeError是ValueError的子类，如果有，也被第一个except给捕获了。
Python所有的错误都是从BaseException类派生的，常见的错误类型和继承关系看这里：
https://docs.python.org/3/library/exceptions.html#exception-hierarchy
＃＃＃＃＃＃＃＃＃＃＃＃＃
#使用try...except捕获错误还有一个巨大的好处，就是可以跨越多层调用，比如函数main()调用foo()，foo()调用bar()，结果bar()出错了，这时，只要main()捕获到了，就可以处理：
def foo(s):
    return 10 / int(s)
def bar(s):
    return foo(s) * 2
def main():
    try:
        bar('0')
    except Exception as e:
        print('Error:', e)
    finally:
        print('finally…')
＃＃＃＃＃＃＃＃＃＃＃
＃＃＃＃＃＃＃＃＃＃＃
2、调用堆栈
如果错误没有被捕获，它就会一直往上抛，最后被Python解释器捕获，打印一个错误信息，然后程序退出。来看看err.py：
# err.py:
def foo(s):
    return 10 / int(s)

def bar(s):
    return foo(s) * 2

def main():
    bar('0')

main()
执行，结果如下：
$ python3 err.py
Traceback (most recent call last):      #提示这是错误的跟踪信息
  File "err.py", line 11, in <module>   #调用main()出错了，在代码文件err.py的第11行代码，但原因是第9行
    main()
  File "err.py", line 9, in main        #调用bar('0')出错了，在代码文件err.py的第9行代码，但原因是第6行
    bar('0')
  File "err.py", line 6, in bar         #原因是return foo(s) * 2这个语句出错了，但这还不是最终原因，继续往下看
    return foo(s) * 2
  File "err.py", line 3, in foo         #原因是return 10 / int(s)这个语句出错了，这是错误产生的源头，因为下面打印了
    return 10 / int(s)
ZeroDivisionError: division by zero
#根据错误类型ZeroDivisionError，我们判断，int(s)本身并没有出错，但是int(s)返回0，在计算10 / 0时出错，至此，找到错误源头。

3、记录错误
如果不捕获错误，自然可以让python解释器来打印出堆栈，但程序也被结束了。既然能捕捉到错误，就可以把错误堆栈打印出来，然后分析错误原因，同时，让程序继续执行下去。
Python内置的logging模块可以非常容易的纪录错误的原因：
# err_logging.py

import logging

def foo(s):
    return 10 / int(s)

def bar(s):
    return foo(s) * 2

def main():
    try:
        bar('0')
    except Exception as e:
        logging.exception(e)

main()
print('END')
#同样是出错，但程序打印完错误信息后会继续执行，并正常退出：
$ python3 err_logging.py
ERROR:root:division by zero
Traceback (most recent call last):
  File "err_logging.py", line 13, in main
    bar('0')
  File "err_logging.py", line 9, in bar
    return foo(s) * 2
  File "err_logging.py", line 6, in foo
    return 10 / int(s)
ZeroDivisionError: division by zero
END
#通过配置，logging还可以把错误记录到日志文件里，方便事后排查


4、抛出错误
# err_reraise.py
def foo(s):
    n = int(s)
    if n==0:
        raise ValueError('invalid value: %s' % s)
    return 10 / n
def bar():
    try:
        foo('0')
    except ValueError as e:
        print('ValueError!')
        raise
bar()
!!!raise语句如果不带参数，就会把当前错误原样抛出!!!
#捕获错误目的只是记录一下，便于后续追踪。但是，由于当前函数不知道应该怎么处理该错误，所以，最恰当的方式是继续往上抛，让顶层调用者去处理。好比一个员工处理不了一个问题时，就把问题抛给他的老板，如果他的老板也处理不了，就一直往上抛，最终会抛给CEO去处理。

try:
    10 / 0
except ZeroDivisionError:
    raise ValueError('input error!')    #在except中raise一个Error，还可以把一种类型的错误转化成另一种类型：
#只要是合理的转换逻辑就可以，但是，决不应该把一个IOError转换成毫不相干的ValueError。

小结:
Python内置的try...except...finally用来处理错误十分方便。出错时，会分析错误信息并定位错误发生的代码位置才是最关键的。
程序也可以主动抛出错误，让调用者来处理相应的错误。但是，应该在文档中写清楚可能会抛出哪些错误，以及错误产生的原因。

```