
```
               异常处理
异常以及异常抛出
     异常抛出机制，为程序开发人员提供了一种在运行时发现错误，
进行恢复处理，然后继续执行的能力。
例：
     #coding:utf8
     filename = raw_input('请输入您要操作的文件：')
     try:
         f =  open(filename)
         print 'hello'
     except IOError,msg:
         print "你指定的文件不存在"

     except NameError,msg:
         print "内部变量调用错误"

     finally:
         print "ok"

     if filename == "hello":
         raise TypeError("nothing!!!")

----------------------------------
finally字句：
     Python提供try-finally字句用来表述这样的情况：我们不关心捕抓不到什么
错误，无论错误是不是发生，这些代码“必须”运行，比如文件关闭，释放锁，把数据库
连接返回给连接池等。比如：
     >>> try:
     ...     f = open('unfile.py','r')
     ... except Exception,e:
     ...     print False,str(e)
     ... finally:
     ...     print "exec finally"
     ...
     False [Errno 2] No such file or directory: 'unfile.py'
     exec finally
     >>>

-----------------------------------
raise抛出异常
     >>> if 'a' > 5:
     ...     raise TypeError("Error:'a'must be integer.")
     ...
     Traceback (most recent call last):
       File "<stdin>", line 2, in <module>
     TypeError: Error:'a'must be integer.
     >>>

-----------------------------------
抛出机制：
     1、如果在运行时发生异常的话，解释器会查找相应的处理语句（称为handler）。
     2、要是在当前函数里没有找到的话，他会将异常传递给上层的调用函数，看看那里能不能处理。
     3、如果在最外层（全局“main”）还是没有找到的话，解释器就会退出，同时
打印出traceback以便让用户找出错误产生的原因。
     #注意：虽然大多数错误会导致异常，但一个异常不一定代表一个错误。有时候它们只是一个警告，
有时候它们可能是一个终止信号，比如退出循环等。


例：
1、     >>> open('abc.txt')
     Traceback (most recent call last):
       File "<stdin>", line 1, in <module>
     IOError: [Errno 2] No such file or directory: 'abc.txt'     #没有这个文件或目录
     >>>
2、     >>> print name
     Traceback (most recent call last):
      File "<stdin>", line 1, in <module>
     NameError: name 'name' is not defined     #name没有被定义过
     >>>
3、



```
